Workbook

Sheet Summary
A1: The Wolf of McKenzie Towne: Season One Budget Summary
A2: All figures in Canadian dollars. Recalculates from the Assumptions, Budget and Funding sheets.
A4: Expenses by category | B4: Lean | C4: Target | D4: Share of Target
A5: 1. Student mentors & placements | B5: =SUMIF(Budget!$A$5:$A$58,$A5,Budget!$E$5:$E$58) -> 5854 | C5: =SUMIF(Budget!$A$5:$A$58,$A5,Budget!$H$5:$H$58) -> 26318.4 | D5: =IF($C$13=0,0,C5/$C$13) -> 0.60860376
A6: 2. Planning sessions | B6: =SUMIF(Budget!$A$5:$A$58,$A6,Budget!$E$5:$E$58) -> 1097 | C6: =SUMIF(Budget!$A$5:$A$58,$A6,Budget!$H$5:$H$58) -> 2950 | D6: =IF($C$13=0,0,C6/$C$13) -> 0.068217714
A7: 3. Costumes & sets | B7: =SUMIF(Budget!$A$5:$A$58,$A7,Budget!$E$5:$E$58) -> 1579 | C7: =SUMIF(Budget!$A$5:$A$58,$A7,Budget!$H$5:$H$58) -> 3454 | D7: =IF($C$13=0,0,C7/$C$13) -> 0.079872537
A8: 4. Race-day operations | B8: =SUMIF(Budget!$A$5:$A$58,$A8,Budget!$E$5:$E$58) -> 470.2 | C8: =SUMIF(Budget!$A$5:$A$58,$A8,Budget!$H$5:$H$58) -> 2793.5 | D8: =IF($C$13=0,0,C8/$C$13) -> 0.064598706
A9: 5. Marketing & media | B9: =SUMIF(Budget!$A$5:$A$58,$A9,Budget!$E$5:$E$58) -> 392.5 | C9: =SUMIF(Budget!$A$5:$A$58,$A9,Budget!$H$5:$H$58) -> 2140 | D9: =IF($C$13=0,0,C9/$C$13) -> 0.049486748
A10: 6. Food (race day & finale) | B10: =SUMIF(Budget!$A$5:$A$58,$A10,Budget!$E$5:$E$58) -> 925 | C10: =SUMIF(Budget!$A$5:$A$58,$A10,Budget!$H$5:$H$58) -> 2283 | D10: =IF($C$13=0,0,C10/$C$13) -> 0.052793573
A11: 7. Recognition & thanks | B11: =SUMIF(Budget!$A$5:$A$58,$A11,Budget!$E$5:$E$58) -> 660 | C11: =SUMIF(Budget!$A$5:$A$58,$A11,Budget!$H$5:$H$58) -> 1700 | D11: =IF($C$13=0,0,C11/$C$13) -> 0.039311903
A12: 8. Insurance, permits & safety | B12: =SUMIF(Budget!$A$5:$A$58,$A12,Budget!$E$5:$E$58) -> 480 | C12: =SUMIF(Budget!$A$5:$A$58,$A12,Budget!$H$5:$H$58) -> 1605 | D12: =IF($C$13=0,0,C12/$C$13) -> 0.037115061
A13: Subtotal | B13: =SUM(B5:B12) -> 11457.7 | C13: =SUM(C5:C12) -> 43243.9
A14: Contingency | B14: =B13*Assumptions!$B$30 -> 1145.77 | C14: =C13*Assumptions!$C$30 -> 6486.585
A15: TOTAL EXPENSES | B15: =B13+B14 -> 12603.47 | C15: =C13+C14 -> 49730.485
A17: Funding & the MTC request | B17: Lean | C17: Target
A18: Funding if every application succeeds (excl. MTC) | B18: =Funding!D15 -> 24064 | C18: =Funding!E15 -> 49679.2
A19: Expected funding (probability-weighted, excl. MTC) | B19: =Funding!H15 -> 13102.8 | C19: =Funding!G15 -> 27481.6
A20: Gap if every application succeeds | B20: =B15-B18 -> -11460.53 | C20: =C15-C18 -> 51.285
A21: Gap at expected funding | B21: =B15-B19 -> -499.33 | C21: =C15-C19 -> 22248.885
A22: Matching required: Inspiring Neighbourhoods (applicant ≥ request) | B22: =Funding!D10 -> 2500 | C22: =Funding!E10 -> 5000
A23: RECOMMENDED MTC CASH REQUEST (larger of expected gap or matching need) | B23: =MAX(0,B21,B22) -> 2500 | C23: =MAX(0,C21,C22) -> 22248.885
A24: In-kind items that could reduce cash needs (items marked Y) | B24: =SUMIF(Budget!$I$5:$I$58,"Y",Budget!$E$5:$E$58) -> 865 | C24: =SUMIF(Budget!$I$5:$I$58,"Y",Budget!$H$5:$H$58) -> 3803
A26: Key ratios | B26: Lean | C26: Target
A27: Racers | B27: =Assumptions!$B$7 -> 48 | C27: =Assumptions!$C$7 -> 64
A28: Cost per racer (total expenses ÷ racers) | B28: =IF(B27=0,0,B15/B27) -> 262.57229 | C28: =IF(C27=0,0,C15/C27) -> 777.03883
A29: Share of costs covered by clan fees | B29: =IF(B15=0,0,Funding!D5/B15) -> 0.028563562 | C29: =IF(C15=0,0,Funding!E5/C15) -> 0.0096520273
A30: Student mentors & placements as share of Target | C30: =IF(C15=0,0,C5/C15) -> 0.52922066
A32: How to read this: Lean = a scrappy first year with borrowed gear and fewer paid roles. Target = doing it right, with paid summer students, a co-op term and full production values.
A33: Canada Summer Jobs and co-op wages appear as both an expense and (if approved) a subsidy, so their net cost is close to zero when funding succeeds.
A34: Placement/admin fees and mentor honoraria are assumptions per your direction; many credit placements carry no fee. Confirm with each school.
A35: Placeholders to confirm: insurance quote, City park/permit fees, app pricing, Towne Hall room rate, current Alberta minimum wage.
A36: Probabilities are planning judgements, not funder guidance. Update them as applications are submitted and decided.

Sheet Assumptions
A1: The Wolf of McKenzie Towne: Budget Assumptions
A2: Blue = inputs you can change. Black = formulas. Yellow = key levers to confirm. Every cost in the Budget sheet is driven from here or from its own row.
A4: Driver | B4: Lean | C4: Target | D4: Notes / source
A5: Clans racing | B5: 12 | C5: 16 | D5: Clans of four teens aged 13–18. Planning estimate.
A6: Teens per clan | B6: 4 | C6: 4 | D6: Event design.
A7: Racers (formula) | B7: =B5*B6 -> 48 | C7: =C5*C6 -> 64 | D7: Clans × teens per clan.
A8: Youth Race Council members | B8: 10 | C8: 12 | D8: Event design: 8–14 teens.
A9: Planning sessions | B9: 12 | C9: 12 | D9: Mission Log: 8 Act I missions + 4 Act II missions.
A10: Attendees per planning session | B10: 14 | C10: 20 | D10: Youth council + student mentors + adult allies.
A11: Planning food per person per session | B11: 4 | C11: 6 | D11: Pizza / snacks / drinks. Planning estimate.
A12: Race-day adult volunteers | B12: 25 | C12: 35 | D12: 2 adults per station, marshals, first aid, food crew.
A13: Finale meal guests beyond racers & volunteers | B13: 60 | C13: 150 | D13: Families, neighbours, sponsors. Planning estimate.
A14: Finale meal cost per person | B14: 5 | C14: 7 | D14: BBQ-style community meal. Lower if food is donated.
A15: Clan entry fee (per clan of 4) | B15: 40 | C15: 40 | D15: Low but present: $10 per teen. User direction.
A16: Share of clans with fee waived (bursary) | B16: 0.25 | C16: 0.25 | D16: So cost never keeps a teen home.
A17: Lantern Mentors (practicum / CSL students) | B17: 2 | C17: 4 | D17: 2 marketing + 2 theatre at Target.
A18: Mentor honorarium per mentor (season) | B18: 400 | C18: 750 | D18: Recognises unpaid placement work; confirm school policy allows it.
A19: Placement / admin fee per mentor | B19: 100 | C19: 250 | D19: ASSUMPTION per user: placements may carry a fee. Many Calgary CSL/practicum programs charge none — confirm with each school.
... A27: Co-op weeks | B27: 12 | C27: 14 | D27: SWPP requires 6–16 weeks, min 180 hours.
A28: Co-op hours per week | B28: 35 | C28: 35
A29: Volunteer & council T-shirts | B29: 30 | C29: 60
A30: Contingency % | B30: 0.1 | C30: 0.15 | D30: First-year event: higher contingency at Target.

Sheet Budget
A1: Expense Budget: Lean vs Target
A2: Qty × Unit cost = Total. Blue = inputs; green = pulled from Assumptions. 'In-kind?' = Y marks items that could be donated or borrowed instead of bought.
A4: Category | B4: Line item | C4: Lean qty | D4: Lean unit $ | E4: Lean total | F4: Target qty | G4: Target unit $ | H4: Target total | I4: In-kind? | J4: Notes / assumption
A5: 1. Student mentors & placements | B5: Lantern Mentor honoraria | C5: =Assumptions!$B$17 -> 2 | D5: =Assumptions!$B$18 -> 400 | E5: =C5*D5 -> 800 | F5: =Assumptions!$C$17 -> 4 | G5: =Assumptions!$C$18 -> 750 | H5: =F5*G5 -> 3000 | J5: Per mentor for the season.
A6: 1. Student mentors & placements | B6: Placement / admin fees | C6: =Assumptions!$B$17 -> 2 | D6: =Assumptions!$B$19 -> 100 | E6: =C6*D6 -> 200 | F6: =Assumptions!$C$17 -> 4 | G6: =Assumptions!$C$19 -> 250 | H6: =F6*G6 -> 1000 | J6: Assumed per user; confirm with MRU, SAIT, U of C.
A7: 1. Student mentors & placements | B7: Mentor police checks (vulnerable sector) | C7: =Assumptions!$B$17 -> 2 | D7: 25 | E7: =C7*D7 -> 50 | F7: =Assumptions!$C$17 -> 4 | G7: 50 | H7: =F7*G7 -> 200 | J7: Planning estimate; confirm Calgary Police Service fee.
A8: 1. Student mentors & placements | B8: Mentor transit / mileage | C8: =Assumptions!$B$17 -> 2 | D8: 50 | E8: =C8*D8 -> 100 | F8: =Assumptions!$C$17 -> 4 | G8: 120 | H8: =F8*G8 -> 480 | J8: Planning estimate.
A9: 1. Student mentors & placements | B9: Canada Summer Jobs assistants (wages + employer costs) | C9: =Assumptions!$B$20 -> 1 | D9: =Assumptions!$B$23*Assumptions!$B$21*Assumptions!$B$22*(1+Assumptions!$B$24) -> 4704 | E9: =C9*D9 -> 4704 | F9: =Assumptions!$C$20 -> 2 | G9: =Assumptions!$C$23*Assumptions!$C$21*Assumptions!$C$22*(1+Assumptions!$C$24) -> 5880 | H9: =F9*G9 -> 11760 | J9: Offset by CSJ subsidy if approved (see Funding).
A10: 1. Student mentors & placements | B10: Co-op marketing student (wages + employer costs) | C10: =Assumptions!$B$25 -> 0 | D10: =Assumptions!$B$26*Assumptions!$B$27*Assumptions!$B$28*(1+Assumptions!$B$24) -> 8467.2 | E10: =C10*D10 -> 0 | F10: =Assumptions!$C$25 -> 1 | G10: =Assumptions!$C$26*Assumptions!$C$27*Assumptions!$C$28*(1+Assumptions!$C$24) -> 9878.4 | H10: =F10*G10 -> 9878.4 | J10: Partly offset by SWPP subsidy if eligible.
A11: 2. Planning sessions | B11: Food at planning sessions | C11: =Assumptions!$B$9 -> 12 | D11: =Assumptions!$B$10*Assumptions!$B$11 -> 56 | E11: =C11*D11 -> 672 | F11: =Assumptions!$C$9 -> 12 | G11: =Assumptions!$C$10*Assumptions!$C$11 -> 120 | H11: =F11*G11 -> 1440 | J11: Every Mission Log meeting.
A12: 2. Planning sessions | B12: Meeting room (McKenzie Towne Hall) | C12: =Assumptions!$B$9 -> 12 | D12: 0 | E12: =C12*D12 -> 0 | F12: =Assumptions!$C$9 -> 12 | G12: 40 | H12: =F12*G12 -> 480 | I12: Y | J12: Ask MTC for in-kind use. Rate is a placeholder.
A13: 2. Planning sessions | B13: Mission Log workbooks (colour print) | C13: =Assumptions!$B$8+4 -> 14 | D13: 15 | E13: =C13*D13 -> 210 | F13: =Assumptions!$C$8+4 -> 16 | G13: 25 | H13: =F13*G13 -> 400 | J13: Council + mentors + adult allies.
A14: 2. Planning sessions | B14: Toolkit photocopy packs & supplies | C14: 1 | D14: 75 | E14: =C14*D14 -> 75 | F14: 1 | G14: 150 | H14: =F14*G14 -> 150 | J14: Cards, markers, chart paper.
A15: 2. Planning sessions | B15: Lantern Meter poster & badge stickers | C15: 1 | D15: 40 | E15: =C15*D15 -> 40 | F15: 1 | G15: 80 | H15: =F15*G15 -> 80
A16: 2. Planning sessions | B16: Act I celebration night | C16: 1 | D16: 0 | E16: =C16*D16 -> 0 | F16: 1 | G16: 100 | H16: =F16*G16 -> 100 | J16: Pizza and a blooper reel after Mission 8.
A17: 2. Planning sessions | B17: Debrief & highlight-reel premiere night | C17: 1 | D17: 100 | E17: =C17*D17 -> 100 | F17: 1 | G17: 300 | H17: =F17*G17 -> 300 | J17: Mission 12; recruits Season Two.
A18: 3. Costumes & sets | B18: Laird Lachlan costume (kilt, sporran, hat) | C18: 1 | D18: 80 | E18: =C18*D18 -> 80 | F18: 1 | G18: 200 | H18: =F18*G18 -> 200 | J18: Rent or buy; may be borrowed from a theatre program.
A19: 3. Costumes & sets | B19: The Wolf costume & mask | C19: 1 | D19: 60 | E19: =C19*D19 -> 60 | F19: 1 | G19: 150 | H19: =F19*G19 -> 150
A20: 3. Costumes & sets | B20: Wolf Pack cloaks | C20: 8 | D20: 20 | E20: =C20*D20 -> 160 | F20: 10 | G20: 30 | H20: =F20*G20 -> 300
A21: 3. Costumes & sets | B21: Dragon costume (Knight's Trial) | C21: 1 | D21: 50 | E21: =C21*D21 -> 50 | F21: 1 | G21: 120 | H21: =F21*G21 -> 120
A22: 3. Costumes & sets | B22: Gazebo Tribunal wigs & robes | C22: 3 | D22: 15 | E22: =C22*D22 -> 45 | F22: 3 | G22: 30 | H22: =F22*G22 -> 90
A23: 3. Costumes & sets | B23: Dodgy Dougal costume | C23: 1 | D23: 20 | E23: =C23*D23 -> 20 | F23: 1 | G23: 40 | H23: =F23*G23 -> 40 | J23: Firetruck Park interrogation.
A24: 3. Costumes & sets | B24: Tartan bandanas (racers + council) | C24: =Assumptions!$B$7+Assumptions!$B$8 -> 58 | D24: 3 | E24: =C24*D24 -> 174 | F24: =Assumptions!$C$7+Assumptions!$C$8 -> 76 | G24: 4 | H24: =F24*G24 -> 304 | J24: Clan colours.
A25: 3. Costumes & sets | B25: Giant Lantern finale prop (frame, LED, fog machine) | C25: 1 | D25: 300 | E25: =C25*D25 -> 300 | F25: 1 | G25: 700 | H25: =F25*G25 -> 700 | J25: The peak-end moment; worth investing in.
A26: 3. Costumes & sets | B26: Station sets & props (8 stations) | C26: 8 | D26: 60 | E26: =C26*D26 -> 480 | F26: 8 | G26: 125 | H26: =F26*G26 -> 1000 | J26: Treasure maps, vault box, magnetic rods, pool noodles, etc.
A27: 3. Costumes & sets | B27: Nessie inflatable & eggs | C27: 1 | D27: 60 | E27: =C27*D27 -> 60 | F27: 1 | G27: 150 | H27: =F27*G27 -> 150
A28: 3. Costumes & sets | B28: Set-building materials (paint, wood, fabric) | C28: 1 | D28: 150 | E28: =C28*D28 -> 150 | F28: 1 | G28: 400 | H28: =F28*G28 -> 400 | J28: Reusable for Season Two.
A29: 4. Race-day operations | B29: Flag belts (racers + spares) | C29: =Assumptions!$B$7+10 -> 58 | D29: 2.5 | E29: =C29*D29 -> 145 | F29: =Assumptions!$C$7+10 -> 74 | G29: 3.5 | H29: =F29*G29 -> 259
A30: 4. Race-day operations | B30: Wolf Pack glow belts | C30: 8 | D30: 8 | E30: =C30*D30 -> 64 | F30: 10 | G30: 12 | H30: =F30*G30 -> 120
A31: 4. Race-day operations | B31: Glow sticks (racers, volunteers, guests) | C31: =Assumptions!$B$7+Assumptions!$B$12+Assumptions!$B$13 -> 133 | D31: 0.4 | E31: =C31*D31 -> 53.2 | F31: =Assumptions!$C$7+Assumptions!$C$12+Assumptions!$C$13 -> 249 | G31: 0.5 | H31: =F31*G31 -> 124.5
A32: 4. Race-day operations | B32: Confetti cannons | C32: 4 | D32: 12 | E32: =C32*D32 -> 48 | F32: 10 | G32: 15 | H32: =F32*G32 -> 150 | J32: Finale.
A33: 4. Race-day operations | B33: Water stations & cups | C33: 1 | D33: 60 | E33: =C33*D33 -> 60 | F33: 1 | G33: 150 | H33: =F33*G33 -> 150
A34: 4. Race-day operations | B34: Tents / canopies | C34: 2 | D34: 0 | E34: =C34*D34 -> 0 | F34: 4 | G34: 60 | H34: =F34*G34 -> 240 | I34: Y | J34: Borrow first; rent if needed.
A35: 4. Race-day operations | B35: Two-way radios | C35: 6 | D35: 0 | E35: =C35*D35 -> 0 | F35: 10 | G35: 25 | H35: =F35*G35 -> 250 | I35: Y | J35: Borrow first; rent if needed.
A36: 4. Race-day operations | B36: Sound system / DJ | C36: 1 | D36: 0 | E36: =C36*D36 -> 0 | F36: 1 | G36: 600 | H36: =F36*G36 -> 600 | I36: Y | J36: Youth DJ with borrowed gear at Lean.
A37: 4. Race-day operations | B37: Portable toilet at Elgin Hill | C37: 0 | D37: 250 | E37: =C37*D37 -> 0 | F37: 1 | G37: 250 | H37: =F37*G37 -> 250 | J37: Towne Hall washrooms may suffice.
A38: 4. Race-day operations | B38: Reflective vests, cones & walk-zone signs | C38: 1 | D38: 100 | E38: =C38*D38 -> 100 | F38: 1 | G38: 250 | H38: =F38*G38 -> 250 | I38: Y
A39: 4. Race-day operations | B39: Scavenger-hunt app (live leaderboard) | C39: 1 | D39: 0 | E39: =C39*D39 -> 0 | F39: 1 | G39: 400 | H39: =F39*G39 -> 400 | J39: Group chat at Lean. App price is a placeholder; confirm non-profit rate.
A40: 5. Marketing & media | B40: Posters (11x17) | C40: 50 | D40: 1.5 | E40: =C40*D40 -> 75 | F40: 150 | G40: 2 | H40: =F40*G40 -> 300 | J40: From the Claude Design poster series.
A41: 5. Marketing & media | B41: Invitation comic print run | C41: 75 | D41: 2.5 | E41: =C41*D41 -> 187.5 | F41: 200 | G41: 3.5 | H41: =F41*G41 -> 700 | J41: Parents, sponsors, volunteers.
...

Sheet Funding
A1: Funding Plan: Revenue, Grants & Subsidies
A2: Probability is a planning judgement (yellow). Weighted = Target × probability. MTC partner cash is calculated on the Summary sheet as the balancing request.
A4: Source | B4: Type | C4: Status | D4: Lean $ | E4: Target $ | F4: Probability | G4: Weighted (Target) | H4: Weighted (Lean) | I4: Deadline / timing | J4: Notes
A5: Clan entry fees (net of bursaries) | B5: Earned | C5: Planned | D5: =Assumptions!$B$5*Assumptions!$B$15*(1-Assumptions!$B$16) -> 360 | E5: =Assumptions!$C$5*Assumptions!$C$15*(1-Assumptions!$C$16) -> 480 | F5: 1 | G5: =E5*F5 -> 480 | H5: =D5*F5 -> 360 | I5: Registration (early summer) | J5: Low fee, with bursaries.
A6: Good Places (Federation of Calgary Communities) | B6: Grant | C6: To apply | D6: 5000 | E6: 7500 | F6: 0.5 | G6: =E6*F6 -> 3750 | H6: =D6*F6 -> 2500 | I6: 30 Oct 2026 | J6: $500–$15,000; community associations get priority. MTCA as applicant.
A7: Neighbour Grants (Calgary Foundation) | B7: Grant | C7: To apply | D7: 5000 | E7: 7500 | F7: 0.5 | G7: =E7*F7 -> 3750 | H7: =D7*F7 -> 2500 | I7: 9 Nov 2026 (confirm) | J7: Up to $10,000; artist fees eligible.
A8: Ward 12 Community Event Fund | B8: Grant | C8: To apply | D8: 1000 | E8: 2500 | F8: 0.6 | G8: =E8*F8 -> 1500 | H8: =D8*F8 -> 600 | I8: Opens 15 Dec 2026 | J8: First come, first served.
A9: Jim Button Youth Grant (Youth Central) | B9: Grant | C9: To apply | D9: 1000 | E9: 2000 | F9: 0.5 | G9: =E9*F9 -> 1000 | H9: =D9*F9 -> 500 | I9: 28 Oct 2026 | J9: Youth-led application with a non-profit partner.
A10: Inspiring Neighbourhoods Grant (City) | B10: Grant (matching) | C10: To apply | D10: 2500 | E10: 5000 | F10: 0.5 | G10: =E10*F10 -> 2500 | H10: =D10*F10 -> 1250 | I10: Rolling | J10: Applicant must match the full request (see Summary).
A11: Arts & Culture Microgrant, Tier 1 (City) | B11: Grant | C11: Watch | D11: 3000 | E11: 5000 | F11: 0.4 | G11: =E11*F11 -> 2000 | H11: =D11*F11 -> 1200 | I11: ~March 2027 (unconfirmed) | J11: Theatre, costumes and finale costs.
A12: Canada Summer Jobs wage subsidy | B12: Subsidy | C12: To apply | D12: =Budget!$E$9 -> 4704 | E12: =Budget!$H$9 -> 11760 | F12: 0.7 | G12: =E12*F12 -> 8232 | H12: =D12*F12 -> 3292.8 | I12: Opens late Oct–Nov 2026 | J12: Non-profits: up to 100% of minimum wage + employment costs.
A13: Student Work Placement Program (co-op) | B13: Subsidy | C13: Explore | D13: =MIN(5000,0.5*Budget!$E$10) -> 0 | E13: =MIN(5000,0.5*Budget!$H$10) -> 4939.2 | F13: 0.5 | G13: =E13*F13 -> 2469.6 | H13: =D13*F13 -> 0 | I13: Via delivery partner | J13: ~50% of wages up to $5,000; eligibility for marketing roles unconfirmed.
A14: Local business sponsors (tiers) | B14: Sponsor | C14: To ask | D14: 1500 | E14: 3000 | F14: 0.6 | G14: =E14*F14 -> 1800 | H14: =D14*F14 -> 900 | I14: Jan–May 2027 | J14: Laird's Circle, Clan Champion, Station Sponsor.
A15: Total (excluding MTC partner cash) | D15: =SUM(D5:D14) -> 24064 | E15: =SUM(E5:E14) -> 49679.2 | G15: =SUM(G5:G14) -> 27481.6 | H15: =SUM(H5:H14) -> 13102.8
A17: Not counted as revenue: Riipen Level UP pays students $1,400 directly; college credit placements carry no wage. In-kind donations are tracked on the Summary sheet.
